Workbook
Name W_Scale: Lookups!$K$5
Name W_Conn: Lookups!$K$6
Name W_5G: Lookups!$K$7
Name W_Geo: Lookups!$K$8
Name W_Lic: Lookups!$K$9
Name Region_Key: Lookups!$A$5:$A$11
Name Region_Factor: Lookups!$B$5:$B$11
Name Status_Key: Lookups!$D$5:$D$8
Name Status_Factor: Lookups!$E$5:$E$8
Name Segment_List: Lookups!$G$5:$G$6
Name Company_List: Companies!$B$5:$B$19
Name Rank_Col: Companies!$M$5:$M$19
Name Score_Col: Companies!$L$5:$L$19

Sheet Read me
A1: Licensee Screening Tracker (Excel template, invented data)
A3: All companies and figures are fictional and for demonstration only. The weights are illustrative, not a real methodology.
A5: What this workbook demonstrates
A6: XLOOKUP: Companies (region and licence factors), Profile (company card), Summary (top 5 by rank)
A7: Named ranges: weights (W_Scale, W_Conn, W_5G, W_Geo, W_Lic), lookup keys and lists, used inside formulas
A8: Data validation dropdowns fed from the Lookups sheet and from the company list
A9: Excel Tables, SUMIFS / COUNTIF / AVERAGEIF summaries, RANK with a tie-breaker
A10: Conditional formatting: score colour scale, priority tiers, licence status, weights check
A11: Power Query: a cleaning query for Raw_Shipments (code on the PQ_Query sheet, expected result on PQ_Expected)
A13: How to try it
A14: 1. Companies sheet: change a Licence status or the 5G flag and watch the Score, Rank and Summary update.
A15: 2. Lookups sheet: change a weight (they should total 100%) or a factor.
... A17: 4. Power Query: follow the steps on PQ_Query (Data > Get Data > From Other Sources > Blank Query > Advanced Editor).

Sheet Companies
A1: Companies: priority scoring
A2: Score = 100 x weighted sum of scale, connected share, 5G plans, region exposure and licence gap. Change inputs in blue.
A4: ID | B4: Company | C4: Region | D4: Segment | E4: Annual units (k) | F4: Connected share | G4: 5G planned | H4: Licence status | I4: Region factor | J4: Status factor | K4: Scale (vs largest) | L4: Priority score | M4: Rank | N4: Tier
A5: 1 | B5: Aurora Motors | C5: Europe | D5: Passenger | E5: 2400 | F5: 0.92 | G5: Yes | H5: Pool licence | I5: =_xlfn.XLOOKUP(C5,Region_Key,Region_Factor,0) -> 0.9 | J5: =_xlfn.XLOOKUP(H5,Status_Key,Status_Factor,0) -> 0 | K5: =E5/MAX($E$5:$E$19) -> 0.77419355 | L5: =ROUND(100*(W_Scale*K5+W_Conn*F5+W_5G*IF(G5="Yes",1,0)+W_Geo*I5+W_Lic*J5),1) -> 61.7 | M5: =RANK(L5,$L$5:$L$19)+COUNTIF($L$5:L5,L5)-1 -> 4 | N5: =IF(L5>=65,"High",IF(L5>=45,"Medium","Low")) -> Medium
A6: 2 | B6: Vantage Auto | C6: North America | D6: Passenger | E6: 1900 | F6: 0.88 | G6: Yes | H6: Pool licence | I6: =_xlfn.XLOOKUP(C6,Region_Key,Region_Factor,0) -> 1 | J6: =_xlfn.XLOOKUP(H6,Status_Key,Status_Factor,0) -> 0 | K6: =E6/MAX($E$5:$E$19) -> 0.61290323 | L6: =ROUND(100*(W_Scale*K6+W_Conn*F6+W_5G*IF(G6="Yes",1,0)+W_Geo*I6+W_Lic*J6),1) -> 58.5 | M6: =RANK(L6,$L$5:$L$19)+COUNTIF($L$5:L6,L6)-1 -> 6 | N6: =IF(L6>=65,"High",IF(L6>=45,"Medium","Low")) -> Medium
A7: 3 | B7: Solstice EV | C7: China | D7: Passenger | E7: 3100 | F7: 0.95 | G7: Yes | H7: In negotiation | I7: =_xlfn.XLOOKUP(C7,Region_Key,Region_Factor,0) -> 0.7 | J7: =_xlfn.XLOOKUP(H7,Status_Key,Status_Factor,0) -> 0.7 | K7: =E7/MAX($E$5:$E$19) -> 1 | L7: =ROUND(100*(W_Scale*K7+W_Conn*F7+W_5G*IF(G7="Yes",1,0)+W_Geo*I7+W_Lic*J7),1) -> 85.8 | M7: =RANK(L7,$L$5:$L$19)+COUNTIF($L$5:L7,L7)-1 -> 1 | N7: =IF(L7>=65,"High",IF(L7>=45,"Medium","Low")) -> High
A8: 4 | B8: Kestrel Mobility | C8: China | D8: Passenger | E8: 1250 | F8: 0.9 | G8: Yes | H8: Unlicensed | I8: =_xlfn.XLOOKUP(C8,Region_Key,Region_Factor,0) -> 0.7 | J8: =_xlfn.XLOOKUP(H8,Status_Key,Status_Factor,0) -> 1 | K8: =E8/MAX($E$5:$E$19) -> 0.40322581 | L8: =ROUND(100*(W_Scale*K8+W_Conn*F8+W_5G*IF(G8="Yes",1,0)+W_Geo*I8+W_Lic*J8),1) -> 79.1 | M8: =RANK(L8,$L$5:$L$19)+COUNTIF($L$5:L8,L8)-1 -> 3 | N8: =IF(L8>=65,"High",IF(L8>=45,"Medium","Low")) -> High
A9: 5 | B9: Bharat Drive Co | C9: India | D9: Passenger | E9: 980 | F9: 0.62 | G9: No | H9: Unlicensed | I9: =_xlfn.XLOOKUP(C9,Region_Key,Region_Factor,0) -> 0.6 | J9: =_xlfn.XLOOKUP(H9,Status_Key,Status_Factor,0) -> 1 | K9: =E9/MAX($E$5:$E$19) -> 0.31612903 | L9: =ROUND(100*(W_Scale*K9+W_Conn*F9+W_5G*IF(G9="Yes",1,0)+W_Geo*I9+W_Lic*J9),1) -> 56.2 | M9: =RANK(L9,$L$5:$L$19)+COUNTIF($L$5:L9,L9)-1 -> 7 | N9: =IF(L9>=65,"High",IF(L9>=45,"Medium","Low")) -> Medium
A10: 6 | B10: Meridian Trucks | C10: Europe | D10: Commercial | E10: 310 | F10: 0.85 | G10: Yes | H10: Pool licence | I10: =_xlfn.XLOOKUP(C10,Region_Key,Region_Factor,0) -> 0.9 | J10: =_xlfn.XLOOKUP(H10,Status_Key,Status_Factor,0) -> 0 | K10: =E10/MAX($E$5:$E$19) -> 0.1 | L10: =ROUND(100*(W_Scale*K10+W_Conn*F10+W_5G*IF(G10="Yes",1,0)+W_Geo*I10+W_Lic*J10),1) -> 43.8 | M10: =RANK(L10,$L$5:$L$19)+COUNTIF($L$5:L10,L10)-1 -> 14 | N10: =IF(L10>=65,"High",IF(L10>=45,"Medium","Low")) -> Low
A11: 7 | B11: Cordillera Motors | C11: Latin America | D11: Passenger | E11: 640 | F11: 0.55 | G11: No | H11: Unlicensed | I11: =_xlfn.XLOOKUP(C11,Region_Key,Region_Factor,0) -> 0.4 | J11: =_xlfn.XLOOKUP(H11,Status_Key,Status_Factor,0) -> 1 | K11: =E11/MAX($E$5:$E$19) -> 0.20645161 | L11: =ROUND(100*(W_Scale*K11+W_Conn*F11+W_5G*IF(G11="Yes",1,0)+W_Geo*I11+W_Lic*J11),1) -> 49.4 | M11: =RANK(L11,$L$5:$L$19)+COUNTIF($L$5:L11,L11)-1 -> 12 | N11: =IF(L11>=65,"High",IF(L11>=45,"Medium","Low")) -> Medium
A12: 8 | B12: Nordlys Vehicles | C12: Europe | D12: Passenger | E12: 720 | F12: 0.94 | G12: Yes | H12: Bilateral licence | I12: =_xlfn.XLOOKUP(C12,Region_Key,Region_Factor,0) -> 0.9 | J12: =_xlfn.XLOOKUP(H12,Status_Key,Status_Factor,0) -> 0.2 | K12: =E12/MAX($E$5:$E$19) -> 0.23225806 | L12: =ROUND(100*(W_Scale*K12+W_Conn*F12+W_5G*IF(G12="Yes",1,0)+W_Geo*I12+W_Lic*J12),1) -> 54.4 | M12: =RANK(L12,$L$5:$L$19)+COUNTIF($L$5:L12,L12)-1 -> 8 | N12: =IF(L12>=65,"High",IF(L12>=45,"Medium","Low")) -> Medium
A13: 9 | B13: Tidewater Trucks | C13: North America | D13: Commercial | E13: 260 | F13: 0.8 | G13: No | H13: In negotiation | I13: =_xlfn.XLOOKUP(C13,Region_Key,Region_Factor,0) -> 1 | J13: =_xlfn.XLOOKUP(H13,Status_Key,Status_Factor,0) -> 0.7 | K13: =E13/MAX($E$5:$E$19) -> 0.083870968 | L13: =ROUND(100*(W_Scale*K13+W_Conn*F13+W_5G*IF(G13="Yes",1,0)+W_Geo*I13+W_Lic*J13),1) -> 50.1 | M13: =RANK(L13,$L$5:$L$19)+COUNTIF($L$5:L13,L13)-1 -> 11 | N13: =IF(L13>=65,"High",IF(L13>=45,"Medium","Low")) -> Medium
A14: 10 | B14: Zenith Two-Wheelers | C14: Southeast Asia | D14: Passenger | E14: 1100 | F14: 0.4 | G14: No | H14: Unlicensed | I14: =_xlfn.XLOOKUP(C14,Region_Key,Region_Factor,0) -> 0.5 | J14: =_xlfn.XLOOKUP(H14,Status_Key,Status_Factor,0) -> 1 | K14: =E14/MAX($E$5:$E$19) -> 0.35483871 | L14: =ROUND(100*(W_Scale*K14+W_Conn*F14+W_5G*IF(G14="Yes",1,0)+W_Geo*I14+W_Lic*J14),1) -> 52.4 | M14: =RANK(L14,$L$5:$L$19)+COUNTIF($L$5:L14,L14)-1 -> 9 | N14: =IF(L14>=65,"High",IF(L14>=45,"Medium","Low")) -> Medium
A15: 11 | B15: Lotus Blossom Auto | C15: China | D15: Passenger | E15: 1750 | F15: 0.93 | G15: Yes | H15: Unlicensed | I15: =_xlfn.XLOOKUP(C15,Region_Key,Region_Factor,0) -> 0.7 | J15: =_xlfn.XLOOKUP(H15,Status_Key,Status_Factor,0) -> 1 | K15: =E15/MAX($E$5:$E$19) -> 0.56451613 | L15: =ROUND(100*(W_Scale*K15+W_Conn*F15+W_5G*IF(G15="Yes",1,0)+W_Geo*I15+W_Lic*J15),1) -> 83.6 | M15: =RANK(L15,$L$5:$L$19)+COUNTIF($L$5:L15,L15)-1 -> 2 | N15: =IF(L15>=65,"High",IF(L15>=45,"Medium","Low")) -> High
A16: 12 | B16: Sahara Motors | C16: Middle East & Africa | D16: Passenger | E16: 420 | F16: 0.5 | G16: No | H16: Unlicensed | I16: =_xlfn.XLOOKUP(C16,Region_Key,Region_Factor,0) -> 0.4 | J16: =_xlfn.XLOOKUP(H16,Status_Key,Status_Factor,0) -> 1 | K16: =E16/MAX($E$5:$E$19) -> 0.13548387 | L16: =ROUND(100*(W_Scale*K16+W_Conn*F16+W_5G*IF(G16="Yes",1,0)+W_Geo*I16+W_Lic*J16),1) -> 46.9 | M16: =RANK(L16,$L$5:$L$19)+COUNTIF($L$5:L16,L16)-1 -> 13 | N16: =IF(L16>=65,"High",IF(L16>=45,"Medium","Low")) -> Medium
... A19: 15 | B19: Harbor City Motors | C19: Southeast Asia | D19: Passenger | E19: 760 | F19: 0.72 | G19: Yes | H19: In negotiation | I19: =_xlfn.XLOOKUP(C19,Region_Key,Region_Factor,0) -> 0.5 | J19: =_xlfn.XLOOKUP(H19,Status_Key,Status_Factor,0) -> 0.7 | K19: =E19/MAX($E$5:$E$19) -> 0.24516129 | L19: =ROUND(100*(W_Scale*K19+W_Conn*F19+W_5G*IF(G19="Yes",1,0)+W_Geo*I19+W_Lic*J19),1) -> 60.4 | M19: =RANK(L19,$L$5:$L$19)+COUNTIF($L$5:L19,L19)-1 -> 5 | N19: =IF(L19>=65,"High",IF(L19>=45,"Medium","Low")) -> Medium

Sheet Profile
A1: Company profile (XLOOKUP card)
A2: Pick a company in the blue cell.
A4: Select company | B4: Kestrel Mobility
A6: Region | B6: =_xlfn.XLOOKUP($B$4,Companies!$B$5:$B$19,Companies!$C$5:$C$19,"n/a") -> China
A7: Segment | B7: =_xlfn.XLOOKUP($B$4,Companies!$B$5:$B$19,Companies!$D$5:$D$19,"n/a") -> Passenger
A8: Annual units (k) | B8: =_xlfn.XLOOKUP($B$4,Companies!$B$5:$B$19,Companies!$E$5:$E$19,"n/a") -> 1250
A9: Connected share | B9: =_xlfn.XLOOKUP($B$4,Companies!$B$5:$B$19,Companies!$F$5:$F$19,"n/a") -> 0.9
A10: 5G planned | B10: =_xlfn.XLOOKUP($B$4,Companies!$B$5:$B$19,Companies!$G$5:$G$19,"n/a") -> Yes
A11: Licence status | B11: =_xlfn.XLOOKUP($B$4,Companies!$B$5:$B$19,Companies!$H$5:$H$19,"n/a") -> Unlicensed
A12: Priority score | B12: =_xlfn.XLOOKUP($B$4,Companies!$B$5:$B$19,Companies!$L$5:$L$19,"n/a") -> 79.1
A13: Rank (of 15) | B13: =_xlfn.XLOOKUP($B$4,Companies!$B$5:$B$19,Companies!$M$5:$M$19,"n/a") -> 3
A14: Tier | B14: =_xlfn.XLOOKUP($B$4,Companies!$B$5:$B$19,Companies!$N$5:$N$19,"n/a") -> High
A16: Gap to top-ranked company (score points) | B16: =_xlfn.XLOOKUP(1,Rank_Col,Score_Col,0)-B12 -> 6.7
A17: Top-ranked company | B17: =_xlfn.XLOOKUP(1,Rank_Col,Company_List,"n/a") -> Solstice EV

Sheet Summary
A1: Summary by region and top targets
A2: Formulas: COUNTIF, SUMIF(S), AVERAGEIF, IFERROR and XLOOKUP on rank.
A4: Region | B4: Companies | C4: Total units (k) | D4: Unlicensed units (k) | E4: Share unlicensed | F4: Average score
A5: =Lookups!A5 -> Europe | B5: =COUNTIF(Companies!$C$5:$C$19,A5) -> 3 | C5: =SUMIF(Companies!$C$5:$C$19,A5,Companies!$E$5:$E$19) -> 3430 | D5: =SUMIFS(Companies!$E$5:$E$19,Companies!$C$5:$C$19,A5,Companies!$H$5:$H$19,"Unlicensed") -> 0 | E5: =IFERROR(D5/C5,0) -> 0 | F5: =IFERROR(AVERAGEIF(Companies!$C$5:$C$19,A5,Companies!$L$5:$L$19),0) -> 53.3
A6: =Lookups!A6 -> North America | B6: =COUNTIF(Companies!$C$5:$C$19,A6) -> 3 | C6: =SUMIF(Companies!$C$5:$C$19,A6,Companies!$E$5:$E$19) -> 2500 | D6: =SUMIFS(Companies!$E$5:$E$19,Companies!$C$5:$C$19,A6,Companies!$H$5:$H$19,"Unlicensed") -> 0 | E6: =IFERROR(D6/C6,0) -> 0 | F6: =IFERROR(AVERAGEIF(Companies!$C$5:$C$19,A6,Companies!$L$5:$L$19),0) -> 53.266667
A7: =Lookups!A7 -> China | B7: =COUNTIF(Companies!$C$5:$C$19,A7) -> 3 | C7: =SUMIF(Companies!$C$5:$C$19,A7,Companies!$E$5:$E$19) -> 6100 | D7: =SUMIFS(Companies!$E$5:$E$19,Companies!$C$5:$C$19,A7,Companies!$H$5:$H$19,"Unlicensed") -> 3000 | E7: =IFERROR(D7/C7,0) -> 0.49180328 | F7: =IFERROR(AVERAGEIF(Companies!$C$5:$C$19,A7,Companies!$L$5:$L$19),0) -> 82.833333
A8: =Lookups!A8 -> India | B8: =COUNTIF(Companies!$C$5:$C$19,A8) -> 2 | C8: =SUMIF(Companies!$C$5:$C$19,A8,Companies!$E$5:$E$19) -> 1170 | D8: =SUMIFS(Companies!$E$5:$E$19,Companies!$C$5:$C$19,A8,Companies!$H$5:$H$19,"Unlicensed") -> 980 | E8: =IFERROR(D8/C8,0) -> 0.83760684 | F8: =IFERROR(AVERAGEIF(Companies!$C$5:$C$19,A8,Companies!$L$5:$L$19),0) -> 48.2
A9: =Lookups!A9 -> Southeast Asia | B9: =COUNTIF(Companies!$C$5:$C$19,A9) -> 2 | C9: =SUMIF(Companies!$C$5:$C$19,A9,Companies!$E$5:$E$19) -> 1860 | D9: =SUMIFS(Companies!$E$5:$E$19,Companies!$C$5:$C$19,A9,Companies!$H$5:$H$19,"Unlicensed") -> 1100 | E9: =IFERROR(D9/C9,0) -> 0.59139785 | F9: =IFERROR(AVERAGEIF(Companies!$C$5:$C$19,A9,Companies!$L$5:$L$19),0) -> 56.4
A10: =Lookups!A10 -> Latin America | B10: =COUNTIF(Companies!$C$5:$C$19,A10) -> 1 | C10: =SUMIF(Companies!$C$5:$C$19,A10,Companies!$E$5:$E$19) -> 640 | D10: =SUMIFS(Companies!$E$5:$E$19,Companies!$C$5:$C$19,A10,Companies!$H$5:$H$19,"Unlicensed") -> 640 | E10: =IFERROR(D10/C10,0) -> 1 | F10: =IFERROR(AVERAGEIF(Companies!$C$5:$C$19,A10,Companies!$L$5:$L$19),0) -> 49.4
A11: =Lookups!A11 -> Middle East & Africa | B11: =COUNTIF(Companies!$C$5:$C$19,A11) -> 1 | C11: =SUMIF(Companies!$C$5:$C$19,A11,Companies!$E$5:$E$19) -> 420 | D11: =SUMIFS(Companies!$E$5:$E$19,Companies!$C$5:$C$19,A11,Companies!$H$5:$H$19,"Unlicensed") -> 420 | E11: =IFERROR(D11/C11,0) -> 1 | F11: =IFERROR(AVERAGEIF(Companies!$C$5:$C$19,A11,Companies!$L$5:$L$19),0) -> 46.9
A12: Total | B12: =SUM(B5:B11) -> 15 | C12: =SUM(C5:C11) -> 16120 | D12: =SUM(D5:D11) -> 6140 | E12: =IFERROR(D12/C12,0) -> 0.3808933
A15: Rank | B15: Company | C15: Region | D15: Licence status | E15: Priority score
A16: 1 | B16: =_xlfn.XLOOKUP($A16,Rank_Col,Companies!$B$5:$B$19,"n/a") -> Solstice EV | C16: =_xlfn.XLOOKUP($A16,Rank_Col,Companies!$C$5:$C$19,"n/a") -> China | D16: =_xlfn.XLOOKUP($A16,Rank_Col,Companies!$H$5:$H$19,"n/a") -> In negotiation | E16: =_xlfn.XLOOKUP($A16,Rank_Col,Companies!$L$5:$L$19,"n/a") -> 85.8
A17: 2 | B17: =_xlfn.XLOOKUP($A17,Rank_Col,Companies!$B$5:$B$19,"n/a") -> Lotus Blossom Auto | C17: =_xlfn.XLOOKUP($A17,Rank_Col,Companies!$C$5:$C$19,"n/a") -> China | D17: =_xlfn.XLOOKUP($A17,Rank_Col,Companies!$H$5:$H$19,"n/a") -> Unlicensed | E17: =_xlfn.XLOOKUP($A17,Rank_Col,Companies!$L$5:$L$19,"n/a") -> 83.6
A18: 3 | B18: =_xlfn.XLOOKUP($A18,Rank_Col,Companies!$B$5:$B$19,"n/a") -> Kestrel Mobility | C18: =_xlfn.XLOOKUP($A18,Rank_Col,Companies!$C$5:$C$19,"n/a") -> China | D18: =_xlfn.XLOOKUP($A18,Rank_Col,Companies!$H$5:$H$19,"n/a") -> Unlicensed | E18: =_xlfn.XLOOKUP($A18,Rank_Col,Companies!$L$5:$L$19,"n/a") -> 79.1
A19: 4 | B19: =_xlfn.XLOOKUP($A19,Rank_Col,Companies!$B$5:$B$19,"n/a") -> Aurora Motors | C19: =_xlfn.XLOOKUP($A19,Rank_Col,Companies!$C$5:$C$19,"n/a") -> Europe | D19: =_xlfn.XLOOKUP($A19,Rank_Col,Companies!$H$5:$H$19,"n/a") -> Pool licence | E19: =_xlfn.XLOOKUP($A19,Rank_Col,Companies!$L$5:$L$19,"n/a") -> 61.7
A20: 5 | B20: =_xlfn.XLOOKUP($A20,Rank_Col,Companies!$B$5:$B$19,"n/a") -> Harbor City Motors | C20: =_xlfn.XLOOKUP($A20,Rank_Col,Companies!$C$5:$C$19,"n/a") -> Southeast Asia | D20: =_xlfn.XLOOKUP($A20,Rank_Col,Companies!$H$5:$H$19,"n/a") -> In negotiation | E20: =_xlfn.XLOOKUP($A20,Rank_Col,Companies!$L$5:$L$19,"n/a") -> 60.4

Sheet Lookups
A1: Lookups and weights
A2: Blue cells are inputs.
A4: Region | B4: Export exposure factor | D4: Licence status | E4: Opportunity factor | G4: Segment | I4: Scoring weight | J4: Name | K4: Weight
A5: Europe | B5: 0.9 | D5: Unlicensed | E5: 1 | G5: Passenger | I5: Scale (annual units) | J5: W_Scale | K5: 0.25
A6: North America | B6: 1 | D6: In negotiation | E6: 0.7 | G6: Commercial | I6: Connected share | J6: W_Conn | K6: 0.15
A7: China | B7: 0.7 | D7: Bilateral licence | E7: 0.2 | I7: 5G models planned | J7: W_5G | K7: 0.15
A8: India | B8: 0.6 | D8: Pool licence | E8: 0 | I8: Region exposure | J8: W_Geo | K8: 0.15
A9: Southeast Asia | B9: 0.5 | I9: Licence gap | J9: W_Lic | K9: 0.3
A10: Latin America | B10: 0.4 | I10: Total (must be 100%) | K10: =SUM(K5:K9) -> 1
A11: Middle East & Africa | B11: 0.4

Sheet Raw_Shipments
A1: Raw monthly shipments (messy on purpose)
A2: Trailing spaces, mixed case, blanks and zeros. The Power Query on PQ_Query cleans this.
A4: Month | B4: Company | C4: Region | D4: Units
A5: 45658 | B5: Aurora Motors | C5: Europe | D5: 197143
A6: 45689 | B6: Aurora Motors | C6: Europe | D6: 197939
A7: 45717 | B7: Aurora Motors | C7: Europe | D7: 181080
A8: 45748 | B8: Aurora Motors | C8: Europe | D8: 217579
A9: 45778 | B9: Aurora Motors | C9: Europe | D9: 175440
A10: 45809 | B10: Aurora Motors | C10: Europe | D10: 172513
A11: 45839 | B11: Aurora Motors | C11: Europe | D11: 209235
A12: 45870 | B12: Aurora Motors | C12: Europe | D12: 0
A13: 45901 | B13: Aurora Motors | C13: Europe
A14: 45931 | B14: Aurora Motors | C14: Europe | D14: 197836
A15: 45962 | B15: Aurora Motors | C15: Europe | D15: 201147
A16: 45992 | B16: Aurora Motors | C16: Europe | D16: 209747
A17: 45658 | B17: Vantage Auto | C17: North America | D17: 181972
A18: 45689 | B18: Vantage Auto | C18: North America | D18: 168204
A19: 45717 | B19: Vantage Auto | C19: North America | D19: 148313
A20: 45748 | B20: Vantage Auto | C20: North America | D20: 153602
A21: 45778 | B21: Vantage Auto | C21: North America
A22: 45809 | B22: Vantage Auto | C22: North America | D22: 144545
A23: 45839 | B23: Vantage Auto | C23: North America | D23: 181150
A24: 45870 | B24: Vantage Auto | C24: North America | D24: 164482
A25: 45901 | B25: Vantage Auto | C25: North America | D25: 138723
A26: 45931 | B26: vantage auto | C26: North America | D26: 170590
A27: 45962 | B27: Vantage Auto | C27: North America | D27: 139383
A28: 45992 | B28: Vantage Auto | C28: North America | D28: 143023
A29: 45658 | B29: Solstice EV | C29: China | D29: 234361
A30: 45689 | B30: solstice ev | C30: China | D30: 269471
A31: 45717 | B31: Solstice EV | C31: China | D31: 236080
A32: 45748 | B32: Solstice EV | C32: China | D32: 281848
A33: 45778 | B33: Solstice EV | C33: China | D33: 235913
... A56: 45748 | B56: Bharat Drive Co | C56: India | D56: 70276
A57: 45778 | B57: Bharat Drive Co | C57: India
A58: 45809 | B58: Bharat Drive Co | C58: India | D58: 85003
A59: 45839 | B59: Bharat Drive Co | C59: India | D59: 77230
A60: 45870 | B60: Bharat Drive Co | C60: India | D60: 82796
A61: 45901 | B61: Bharat Drive Co | C61: India | D61: 87475
A62: 45931 | B62: Bharat Drive Co | C62: India | D62: 91834
A63: 45962 | B63: Bharat Drive Co | C63: India | D63: 91487
...

Sheet PQ_Query
A1: Power Query: clean and summarise Raw_Shipments
A2: Paste the code below into a blank query. Result: one row per company.
A3: 1. Data > Get Data > From Other Sources > Blank Query.
A4: 2. In the Power Query window choose Home > Advanced Editor.
A5: 3. Delete the placeholder text and paste the M code from A9 downward, then Done.
A6: 4. Home > Close & Load To... > Table, on a new sheet.
A7: 5. Compare your result with the PQ_Expected sheet.
A8: M code
A9: let
A10: Source = Excel.CurrentWorkbook(){[Name="tblRawShipments"]}[Content],
A11: Typed = Table.TransformColumnTypes(Source, {{"Month", type date}, {"Company", type text}, {"Region", type text}, {"Units", Int64.Type}}),
A12: Cleaned = Table.TransformColumns(Typed, {{"Company", each Text.Proper(Text.Trim(_)), type text}}),
... A17: Sorted

Sheet PQ_Expected
A1: Expected Power Query result (static preview)
A2: Static values computed independently, for comparing with your loaded query.
A4: Company | B4: Units (12m) | C4: Months reported
A5: Solstice EV | B5: 3081591 | C5: 12
A6: Aurora Motors | B6: 1959659 | C6: 10
A7: Lotus Blossom Auto | B7: 1736096 | C7: 12
A8: Vantage Auto | B8: 1733987 | C8: 11
A9: Kestrel Mobility | B9: 1214847 | C9: 12
A10: Zenith Two-Wheelers | B10: 1074884 | C10: 11
A11: Bharat Drive Co | B11: 935918 | C11: 11
A12: Nordlys Vehicles | B12: 677184 | C12: 11
A13: Harbor City Motors | B13: 674166 | C13: 11
A14: Cordillera Motors | B14: 598871 | C14: 11
A15: Sahara Motors | B15: 436499 | C15: 12
A16: Atlas Utility Vehicles | B16: 356344 | C16: 12
... A19: Pinnacle Commercial | B19: 184913 | C19: 12
